<?xml version="1.0" ?>
<sdf version="1.6">

  <!-- Important: This file is generated. DO NOT EDIT! -->

  <model name="robotx_dock_2018_base_dynamic">
    
    <!--
      This is how this dock should look like:

          X  X          X  X          X  X          XXXX          XXXX          X  X          X  X          X  X    
    -->




    <!-- Row 0 -->
    <include>
      <name>dock_block_0_0</name>
      <pose>0 0 0.25 0 0 0</pose>
        <uri>model://dock_block_4x4_dynamic</uri>
    </include>
    <include>
      <name>dock_block_0_3</name>
      <pose>0 6 0.25 0 0 0</pose>
        <uri>model://dock_block_4x4_dynamic</uri>
    </include>

    <!-- Row 1 -->
    <include>
      <name>dock_block_1_0</name>
      <pose>2 0 0.25 0 0 0</pose>
        <uri>model://dock_block_4x4_dynamic</uri>
    </include>
    <include>
      <name>dock_block_1_3</name>
      <pose>2 6 0.25 0 0 0</pose>
        <uri>model://dock_block_4x4_dynamic</uri>
    </include>

    <!-- Row 2 -->
    <include>
      <name>dock_block_2_0</name>
      <pose>4 0 0.25 0 0 0</pose>
        <uri>model://dock_block_4x4_dynamic</uri>
    </include>
    <include>
      <name>dock_block_2_3</name>
      <pose>4 6 0.25 0 0 0</pose>
        <uri>model://dock_block_4x4_dynamic</uri>
    </include>

    <!-- Row 3 -->
    <include>
      <name>dock_block_3_0</name>
      <pose>6 0 0.25 0 0 0</pose>
        <uri>model://dock_block_4x4_dynamic</uri>
    </include>
    <include>
      <name>dock_block_3_1</name>
      <pose>6 2 0.25 0 0 0</pose>
        <uri>model://dock_block_4x4_dynamic</uri>
    </include>
    <include>
      <name>dock_block_3_2</name>
      <pose>6 4 0.25 0 0 0</pose>
        <uri>model://dock_block_4x4_dynamic</uri>
    </include>
    <include>
      <name>dock_block_3_3</name>
      <pose>6 6 0.25 0 0 0</pose>
        <uri>model://dock_block_4x4_dynamic</uri>
    </include>

    <!-- Row 4 -->
    <include>
      <name>dock_block_4_0</name>
      <pose>8 0 0.25 0 0 0</pose>
        <uri>model://dock_block_4x4_dynamic</uri>
    </include>
    <include>
      <name>dock_block_4_1</name>
      <pose>8 2 0.25 0 0 0</pose>
        <uri>model://dock_block_4x4_dynamic</uri>
    </include>
    <include>
      <name>dock_block_4_2</name>
      <pose>8 4 0.25 0 0 0</pose>
        <uri>model://dock_block_4x4_dynamic</uri>
    </include>
    <include>
      <name>dock_block_4_3</name>
      <pose>8 6 0.25 0 0 0</pose>
        <uri>model://dock_block_4x4_dynamic</uri>
    </include>

    <!-- Row 5 -->
    <include>
      <name>dock_block_5_0</name>
      <pose>10 0 0.25 0 0 0</pose>
        <uri>model://dock_block_4x4_dynamic</uri>
    </include>
    <include>
      <name>dock_block_5_3</name>
      <pose>10 6 0.25 0 0 0</pose>
        <uri>model://dock_block_4x4_dynamic</uri>
    </include>

    <!-- Row 6 -->
    <include>
      <name>dock_block_6_0</name>
      <pose>12 0 0.25 0 0 0</pose>
        <uri>model://dock_block_4x4_dynamic</uri>
    </include>
    <include>
      <name>dock_block_6_3</name>
      <pose>12 6 0.25 0 0 0</pose>
        <uri>model://dock_block_4x4_dynamic</uri>
    </include>

    <!-- Row 7 -->
    <include>
      <name>dock_block_7_0</name>
      <pose>14 0 0.25 0 0 0</pose>
        <uri>model://dock_block_4x4_dynamic</uri>
    </include>
    <include>
      <name>dock_block_7_3</name>
      <pose>14 6 0.25 0 0 0</pose>
        <uri>model://dock_block_4x4_dynamic</uri>
    </include>




    <!-- Add joints across rows -->

    <!-- Row 0 -->

    <!-- Row 1 -->

    <!-- Row 2 -->

    <!-- Row 3 -->
    <joint name="3_0_to_3_1" type="revolute">
      <pose> 0  1.0 0 0 0 0</pose>
      <parent>dock_block_3_1::link</parent>
      <child>dock_block_3_0::link</child>
      <axis>
        <limit>
          <lower>-0.1</lower>
          <upper>0.1</upper>
        </limit>
        <xyz>1 0 0</xyz>
      </axis>
    </joint>
    <joint name="3_1_to_3_2" type="revolute">
      <pose> 0  1.0 0 0 0 0</pose>
      <parent>dock_block_3_2::link</parent>
      <child>dock_block_3_1::link</child>
      <axis>
        <limit>
          <lower>-0.1</lower>
          <upper>0.1</upper>
        </limit>
        <xyz>1 0 0</xyz>
      </axis>
    </joint>
    <joint name="3_2_to_3_3" type="revolute">
      <pose> 0  1.0 0 0 0 0</pose>
      <parent>dock_block_3_3::link</parent>
      <child>dock_block_3_2::link</child>
      <axis>
        <limit>
          <lower>-0.1</lower>
          <upper>0.1</upper>
        </limit>
        <xyz>1 0 0</xyz>
      </axis>
    </joint>

    <!-- Row 4 -->
    <joint name="4_0_to_4_1" type="revolute">
      <pose> 0  1.0 0 0 0 0</pose>
      <parent>dock_block_4_1::link</parent>
      <child>dock_block_4_0::link</child>
      <axis>
        <limit>
          <lower>-0.1</lower>
          <upper>0.1</upper>
        </limit>
        <xyz>1 0 0</xyz>
      </axis>
    </joint>
    <joint name="4_1_to_4_2" type="revolute">
      <pose> 0  1.0 0 0 0 0</pose>
      <parent>dock_block_4_2::link</parent>
      <child>dock_block_4_1::link</child>
      <axis>
        <limit>
          <lower>-0.1</lower>
          <upper>0.1</upper>
        </limit>
        <xyz>1 0 0</xyz>
      </axis>
    </joint>
    <joint name="4_2_to_4_3" type="revolute">
      <pose> 0  1.0 0 0 0 0</pose>
      <parent>dock_block_4_3::link</parent>
      <child>dock_block_4_2::link</child>
      <axis>
        <limit>
          <lower>-0.1</lower>
          <upper>0.1</upper>
        </limit>
        <xyz>1 0 0</xyz>
      </axis>
    </joint>

    <!-- Row 5 -->

    <!-- Row 6 -->

    <!-- Row 7 -->



    <!-- Add joints across columns -->

    <!-- Column 0 -->
    <joint name="1_0_to_0_0" type="revolute">
      <pose> 1.0 0 0 0 0 0</pose>
      <parent>dock_block_1_0::link</parent>
      <child>dock_block_0_0::link</child>
      <axis>
        <limit>
          <lower>-0.1</lower>
          <upper>0.1</upper>
        </limit>
        <xyz>0 1 0</xyz>
      </axis>
    </joint>
    <joint name="2_0_to_1_0" type="revolute">
      <pose> 1.0 0 0 0 0 0</pose>
      <parent>dock_block_2_0::link</parent>
      <child>dock_block_1_0::link</child>
      <axis>
        <limit>
          <lower>-0.1</lower>
          <upper>0.1</upper>
        </limit>
        <xyz>0 1 0</xyz>
      </axis>
    </joint>
    <joint name="3_0_to_2_0" type="revolute">
      <pose> 1.0 0 0 0 0 0</pose>
      <parent>dock_block_3_0::link</parent>
      <child>dock_block_2_0::link</child>
      <axis>
        <limit>
          <lower>-0.1</lower>
          <upper>0.1</upper>
        </limit>
        <xyz>0 1 0</xyz>
      </axis>
    </joint>
    <joint name="4_0_to_3_0" type="revolute">
      <pose> 1.0 0 0 0 0 0</pose>
      <parent>dock_block_4_0::link</parent>
      <child>dock_block_3_0::link</child>
      <axis>
        <limit>
          <lower>-0.1</lower>
          <upper>0.1</upper>
        </limit>
        <xyz>0 1 0</xyz>
      </axis>
    </joint>
    <joint name="5_0_to_4_0" type="revolute">
      <pose> 1.0 0 0 0 0 0</pose>
      <parent>dock_block_5_0::link</parent>
      <child>dock_block_4_0::link</child>
      <axis>
        <limit>
          <lower>-0.1</lower>
          <upper>0.1</upper>
        </limit>
        <xyz>0 1 0</xyz>
      </axis>
    </joint>
    <joint name="6_0_to_5_0" type="revolute">
      <pose> 1.0 0 0 0 0 0</pose>
      <parent>dock_block_6_0::link</parent>
      <child>dock_block_5_0::link</child>
      <axis>
        <limit>
          <lower>-0.1</lower>
          <upper>0.1</upper>
        </limit>
        <xyz>0 1 0</xyz>
      </axis>
    </joint>
    <joint name="7_0_to_6_0" type="revolute">
      <pose> 1.0 0 0 0 0 0</pose>
      <parent>dock_block_7_0::link</parent>
      <child>dock_block_6_0::link</child>
      <axis>
        <limit>
          <lower>-0.1</lower>
          <upper>0.1</upper>
        </limit>
        <xyz>0 1 0</xyz>
      </axis>
    </joint>

    <!-- Column 1 -->
    <joint name="4_1_to_3_1" type="revolute">
      <pose> 1.0 0 0 0 0 0</pose>
      <parent>dock_block_4_1::link</parent>
      <child>dock_block_3_1::link</child>
      <axis>
        <limit>
          <lower>-0.1</lower>
          <upper>0.1</upper>
        </limit>
        <xyz>0 1 0</xyz>
      </axis>
    </joint>

    <!-- Column 2 -->
    <joint name="4_2_to_3_2" type="revolute">
      <pose> 1.0 0 0 0 0 0</pose>
      <parent>dock_block_4_2::link</parent>
      <child>dock_block_3_2::link</child>
      <axis>
        <limit>
          <lower>-0.1</lower>
          <upper>0.1</upper>
        </limit>
        <xyz>0 1 0</xyz>
      </axis>
    </joint>

    <!-- Column 3 -->
    <joint name="1_3_to_0_3" type="revolute">
      <pose> 1.0 0 0 0 0 0</pose>
      <parent>dock_block_1_3::link</parent>
      <child>dock_block_0_3::link</child>
      <axis>
        <limit>
          <lower>-0.1</lower>
          <upper>0.1</upper>
        </limit>
        <xyz>0 1 0</xyz>
      </axis>
    </joint>
    <joint name="2_3_to_1_3" type="revolute">
      <pose> 1.0 0 0 0 0 0</pose>
      <parent>dock_block_2_3::link</parent>
      <child>dock_block_1_3::link</child>
      <axis>
        <limit>
          <lower>-0.1</lower>
          <upper>0.1</upper>
        </limit>
        <xyz>0 1 0</xyz>
      </axis>
    </joint>
    <joint name="3_3_to_2_3" type="revolute">
      <pose> 1.0 0 0 0 0 0</pose>
      <parent>dock_block_3_3::link</parent>
      <child>dock_block_2_3::link</child>
      <axis>
        <limit>
          <lower>-0.1</lower>
          <upper>0.1</upper>
        </limit>
        <xyz>0 1 0</xyz>
      </axis>
    </joint>
    <joint name="4_3_to_3_3" type="revolute">
      <pose> 1.0 0 0 0 0 0</pose>
      <parent>dock_block_4_3::link</parent>
      <child>dock_block_3_3::link</child>
      <axis>
        <limit>
          <lower>-0.1</lower>
          <upper>0.1</upper>
        </limit>
        <xyz>0 1 0</xyz>
      </axis>
    </joint>
    <joint name="5_3_to_4_3" type="revolute">
      <pose> 1.0 0 0 0 0 0</pose>
      <parent>dock_block_5_3::link</parent>
      <child>dock_block_4_3::link</child>
      <axis>
        <limit>
          <lower>-0.1</lower>
          <upper>0.1</upper>
        </limit>
        <xyz>0 1 0</xyz>
      </axis>
    </joint>
    <joint name="6_3_to_5_3" type="revolute">
      <pose> 1.0 0 0 0 0 0</pose>
      <parent>dock_block_6_3::link</parent>
      <child>dock_block_5_3::link</child>
      <axis>
        <limit>
          <lower>-0.1</lower>
          <upper>0.1</upper>
        </limit>
        <xyz>0 1 0</xyz>
      </axis>
    </joint>
    <joint name="7_3_to_6_3" type="revolute">
      <pose> 1.0 0 0 0 0 0</pose>
      <parent>dock_block_7_3::link</parent>
      <child>dock_block_6_3::link</child>
      <axis>
        <limit>
          <lower>-0.1</lower>
          <upper>0.1</upper>
        </limit>
        <xyz>0 1 0</xyz>
      </axis>
    </joint>



  </model>
</sdf>
