<?xml version="1.0"?>
<sdf version='1.5'>
  <model name='plane_gimbal'>
    <pose>0 0 0.246 0 0 0</pose>
    <link name='base_link'>
      <pose>0 0 0 0 0 0</pose>
      <inertial>
        <pose>0 0 0 0 0 0</pose>
        <mass>1.5</mass>
        <inertia>
          <ixx>0.197563</ixx>
          <ixy>0</ixy>
          <ixz>0</ixz>
          <iyy>0.1458929</iyy>
          <iyz>0</iyz>
          <izz>0.1477</izz>
        </inertia>
      </inertial>
      <collision name='base_link_collision'>
        <pose>0 0 -0.07 0 0 0</pose>
        <geometry>
          <box>
            <size>0.47 0.47 0.11</size>
          </box>
        </geometry>
        <surface>
          <contact>
            <ode>
              <max_vel>10</max_vel>
              <min_depth>0.01</min_depth>
            </ode>
          </contact>
          <!--<friction>
            <ode/>
          </friction>-->
        </surface>
      </collision>
      <visual name='base_link_visual'>
        <pose>0.07 0 -0.08 0 0 0</pose>
        <geometry>
          <mesh>
            <scale>0.1 0.1 0.1</scale>
            <uri>model://plane/meshes/body.dae</uri>
          </mesh>
        </geometry>
        <material>
          <script>
            <name>Gazebo/DarkGrey</name>
            <uri>__default__</uri>
          </script>
        </material>
      </visual>
      <gravity>1</gravity>
      <velocity_decay/>
      <self_collide>0</self_collide>
    </link>
    <link name='plane_gimbal/imu_link'>
      <pose>0 0 0 0 0 0</pose>
      <inertial>
        <pose>0 0 0 0 0 0</pose>
        <mass>0.015</mass>
        <inertia>
          <ixx>1e-05</ixx>
          <ixy>0</ixy>
          <ixz>0</ixz>
          <iyy>1e-05</iyy>
          <iyz>0</iyz>
          <izz>1e-05</izz>
        </inertia>
      </inertial>
    </link>
    <joint name='plane_gimbal/imu_joint' type='revolute'>
      <child>plane_gimbal/imu_link</child>
      <parent>base_link</parent>
      <axis>
        <xyz>1 0 0</xyz>
        <limit>
          <lower>0</lower>
          <upper>0</upper>
          <effort>0</effort>
          <velocity>0</velocity>
        </limit>
        <dynamics>
          <spring_reference>0</spring_reference>
          <spring_stiffness>0</spring_stiffness>
        </dynamics>
        <use_parent_model_frame>1</use_parent_model_frame>
      </axis>
    </joint>
    <link name='plane_gimbal/airspeed_link'>
      <pose>0 0 0 0 0 0</pose>
      <inertial>
        <pose>0 0 0 0 0 0</pose>
        <mass>0.015</mass>
        <inertia>
          <ixx>1e-05</ixx>
          <ixy>0</ixy>
          <ixz>0</ixz>
          <iyy>1e-05</iyy>
          <iyz>0</iyz>
          <izz>1e-05</izz>
        </inertia>
      </inertial>
    </link>
    <joint name='plane_gimbal/airspeed_joint' type='revolute'>
      <child>plane_gimbal/airspeed_link</child>
      <parent>base_link</parent>
      <axis>
        <xyz>1 0 0</xyz>
        <limit>
          <lower>0</lower>
          <upper>0</upper>
          <effort>0</effort>
          <velocity>0</velocity>
        </limit>
        <dynamics>
          <spring_reference>0</spring_reference>
          <spring_stiffness>0</spring_stiffness>
        </dynamics>
        <use_parent_model_frame>1</use_parent_model_frame>
      </axis>
    </joint>
    <link name='rotor_puller'>
      <pose>0.3 0 0.0 0 1.57 0</pose>
      <inertial>
        <pose>0 0 0 0 0 0</pose>
        <mass>0.005</mass>
        <inertia>
          <ixx>9.75e-07</ixx>
          <ixy>0</ixy>
          <ixz>0</ixz>
          <iyy>0.000166704</iyy>
          <iyz>0</iyz>
          <izz>0.000167604</izz>
        </inertia>
      </inertial>
      <collision name='rotor_puller_collision'>
        <pose>0.0 0 0.0 0 0 0</pose>
        <geometry>
          <cylinder>
            <length>0.005</length>
            <radius>0.1</radius>
          </cylinder>
        </geometry>
        <surface>
          <contact>
            <ode/>
          </contact>
          <friction>
            <ode/>
          </friction>
        </surface>
      </collision>
      <visual name='rotor_puller_visual'>
        <pose>0 0 -0.09 0 0 0</pose>
        <geometry>
          <mesh>
            <scale>1 1 1</scale>
            <uri>model://plane/meshes/iris_prop_ccw.dae</uri>
          </mesh>
        </geometry>
        <material>
          <script>
            <name>Gazebo/Blue</name>
            <uri>__default__</uri>
          </script>
        </material>
      </visual>
      <gravity>1</gravity>
      <velocity_decay/>
      <self_collide>0</self_collide>
    </link>
    <joint name='rotor_puller_joint' type='revolute'>
      <child>rotor_puller</child>
      <parent>base_link</parent>
      <axis>
        <xyz>1 0 0</xyz>
        <limit>
          <lower>-1e+16</lower>
          <upper>1e+16</upper>
        </limit>
        <dynamics>
          <spring_reference>0</spring_reference>
          <spring_stiffness>0</spring_stiffness>
        </dynamics>
        <use_parent_model_frame>1</use_parent_model_frame>
      </axis>
    </joint>

    <link name="left_elevon">
      <inertial>
        <mass>0.00000001</mass>
        <inertia>
          <ixx>0.000001</ixx>
          <ixy>0.0</ixy>
          <iyy>0.000001</iyy>
          <ixz>0.0</ixz>
          <iyz>0.0</iyz>
          <izz>0.000001</izz>
        </inertia>
        <pose>0 0.3 0 0.00 0 0.0</pose>
      </inertial>
      <visual name='left_elevon_visual'>
        <pose>0.07 0.0 -0.08 0.00 0 0.0</pose>
        <geometry>
          <mesh>
            <scale>0.1 0.1 0.1</scale>
            <uri>model://plane/meshes/left_aileron.dae</uri>
          </mesh>
        </geometry>
        <material>
          <script>
            <name>Gazebo/Blue</name>
            <uri>__default__</uri>
          </script>
        </material>
      </visual>
    </link>
    <link name="right_elevon">
      <inertial>
        <mass>0.00000001</mass>
        <inertia>
          <ixx>0.000001</ixx>
          <ixy>0.0</ixy>
          <iyy>0.000001</iyy>
          <ixz>0.0</ixz>
          <iyz>0.0</iyz>
          <izz>0.000001</izz>
        </inertia>
        <pose>0 -0.3 0 0.00 0 0.0</pose>
      </inertial>
      <visual name='right_elevon_visual'>
        <pose>0.07 0.0 -0.08 0.00 0 0.0</pose>
        <geometry>
          <mesh>
            <scale>0.1 0.1 0.1</scale>
            <uri>model://plane/meshes/right_aileron.dae</uri>
          </mesh>
        </geometry>
        <material>
          <script>
            <name>Gazebo/Blue</name>
            <uri>__default__</uri>
          </script>
        </material>
      </visual>
    </link>
    <link name="left_flap">
      <inertial>
        <mass>0.00000001</mass>
        <inertia>
          <ixx>0.000001</ixx>
          <ixy>0.0</ixy>
          <iyy>0.000001</iyy>
          <ixz>0.0</ixz>
          <iyz>0.0</iyz>
          <izz>0.000001</izz>
        </inertia>
        <pose>0 0.15 0 0.00 0 0.0</pose>
      </inertial>
      <visual name='left_flap_visual'>
        <pose>0.07 0.0 -0.08 0.00 0 0.0</pose>
        <geometry>
          <mesh>
            <scale>0.1 0.1 0.1</scale>
            <uri>model://plane/meshes/left_flap.dae</uri>
          </mesh>
        </geometry>
        <material>
          <script>
            <name>Gazebo/Blue</name>
            <uri>__default__</uri>
          </script>
        </material>
      </visual>
    </link>
    <link name="right_flap">
      <inertial>
        <mass>0.00000001</mass>
        <inertia>
          <ixx>0.000001</ixx>
          <ixy>0.0</ixy>
          <iyy>0.000001</iyy>
          <ixz>0.0</ixz>
          <iyz>0.0</iyz>
          <izz>0.000001</izz>
        </inertia>
        <pose>0 -0.15 0 0.00 0 0.0</pose>
      </inertial>
      <visual name='right_flap_visual'>
        <pose>0.07 0.0 -0.08 0.00 0 0.0</pose>
        <geometry>
          <mesh>
            <scale>0.1 0.1 0.1</scale>
            <uri>model://plane/meshes/right_flap.dae</uri>
          </mesh>
        </geometry>
        <material>
          <script>
            <name>Gazebo/Blue</name>
            <uri>__default__</uri>
          </script>
        </material>
      </visual>
    </link>
    <link name="elevator">
      <inertial>
        <mass>0.00000001</mass>
        <inertia>
          <ixx>0.000001</ixx>
          <ixy>0.0</ixy>
          <iyy>0.000001</iyy>
          <ixz>0.0</ixz>
          <iyz>0.0</iyz>
          <izz>0.000001</izz>
        </inertia>
        <pose> -0.5 0 0 0.00 0 0.0</pose>
      </inertial>
      <visual name='elevator_visual'>
        <pose>0.07 0.0 -0.08 0.00 0 0.0</pose>
        <geometry>
          <mesh>
            <scale>0.1 0.1 0.1</scale>
            <uri>model://plane/meshes/elevators.dae</uri>
          </mesh>
        </geometry>
        <material>
          <script>
            <name>Gazebo/Blue</name>
            <uri>__default__</uri>
          </script>
        </material>
      </visual>
    </link>
    <link name="rudder">
      <inertial>
        <mass>0.00000001</mass>
        <inertia>
          <ixx>0.000001</ixx>
          <ixy>0.0</ixy>
          <iyy>0.000001</iyy>
          <ixz>0.0</ixz>
          <iyz>0.0</iyz>
          <izz>0.000001</izz>
        </inertia>
        <pose>-0.5 0 0.05 0 0 0 </pose>
      </inertial>
      <visual name='rudder_visual'>
        <pose>0.07 0.0 -0.08 0.00 0 0.0</pose>
        <geometry>
          <mesh>
            <scale>0.1 0.1 0.1</scale>
            <uri>model://plane/meshes/rudder.dae</uri>
          </mesh>
        </geometry>
        <material>
          <script>
            <name>Gazebo/Blue</name>
            <uri>__default__</uri>
          </script>
        </material>
      </visual>
    </link>
    <joint name='left_elevon_joint' type='revolute'>
      <parent>base_link</parent>
      <child>left_elevon</child>
      <pose>-0.07 0.4 0.08 0.00 0 0.0</pose>
      <axis>
        <xyz>0 1 0</xyz>
        <limit>
          <!-- -30/+30 deg. -->
          <lower>-0.53</lower>
          <upper>0.53</upper>
        </limit>
        <dynamics>
          <damping>1.000</damping>
        </dynamics>
      </axis>
      <physics>
        <ode>
          <implicit_spring_damper>1</implicit_spring_damper>
        </ode>
      </physics>
    </joint>
    <joint name='right_elevon_joint' type='revolute'>
      <parent>base_link</parent>
      <child>right_elevon</child>
      <pose>-0.07 -0.4 0.08 0.00 0 0.0</pose>
      <axis>
        <xyz>0 1 0</xyz>
        <limit>
          <!-- -30/+30 deg. -->
          <lower>-0.53</lower>
          <upper>0.53</upper>
        </limit>
        <dynamics>
          <damping>1.000</damping>
        </dynamics>
      </axis>
      <physics>
        <ode>
          <implicit_spring_damper>1</implicit_spring_damper>
        </ode>
      </physics>
    </joint>
    <joint name='left_flap_joint' type='revolute'>
      <parent>base_link</parent>
      <child>left_flap</child>
      <pose>-0.07 0.2 0.08 0.00 0 0.0</pose>
      <axis>
        <xyz>0 1 0</xyz>
        <limit>
          <!-- -30/+30 deg. -->
          <lower>-0.53</lower>
          <upper>0.53</upper>
        </limit>
        <dynamics>
          <damping>1.000</damping>
        </dynamics>
      </axis>
      <physics>
        <ode>
          <implicit_spring_damper>1</implicit_spring_damper>
        </ode>
      </physics>
    </joint>
    <joint name='right_flap_joint' type='revolute'>
      <parent>base_link</parent>
      <child>right_flap</child>
      <pose>-0.07 -0.2 0.08 0.00 0 0.0</pose>
      <axis>
        <xyz>0 1 0</xyz>
        <limit>
          <!-- -30/+30 deg. -->
          <lower>-0.53</lower>
          <upper>0.53</upper>
        </limit>
        <dynamics>
          <damping>1.000</damping>
        </dynamics>
      </axis>
      <physics>
        <ode>
          <implicit_spring_damper>1</implicit_spring_damper>
        </ode>
      </physics>
    </joint>
    <joint name='elevator_joint' type='revolute'>
      <parent>base_link</parent>
      <child>elevator</child>
      <pose> -0.5 0 0 0 0 0</pose>
      <axis>
        <xyz>0 1 0</xyz>
        <limit>
          <!-- -30/+30 deg. -->
          <lower>-0.53</lower>
          <upper>0.53</upper>
        </limit>
        <dynamics>
          <damping>1.000</damping>
        </dynamics>
      </axis>
      <physics>
        <ode>
          <implicit_spring_damper>1</implicit_spring_damper>
        </ode>
      </physics>
    </joint>
    <joint name='rudder_joint' type='revolute'>
      <parent>base_link</parent>
      <child>rudder</child>
      <pose>-0.5 0 0.05 0.00 0 0.0</pose>
      <axis>
        <xyz>0 0 1</xyz>
        <limit>
          <!-- -30/+30 deg. -->
          <lower>-0.53</lower>
          <upper>0.53</upper>
        </limit>
        <dynamics>
          <damping>1.000</damping>
        </dynamics>
      </axis>
      <physics>
        <ode>
          <implicit_spring_damper>1</implicit_spring_damper>
        </ode>
      </physics>
    </joint>
    <include>
      <uri>model://gps</uri>
      <pose>0 0 0 0 0 0</pose>
      <name>gps</name>
    </include>
    <joint name='gps_joint' type='fixed'>
      <child>gps::link</child>
      <parent>base_link</parent>
    </joint>
    <plugin name="left_wing" filename="libLiftDragPlugin.so">
      <a0>0.05984281113</a0>
      <cla>4.752798721</cla>
      <cda>0.6417112299</cda>
      <cma>0.0</cma>
      <alpha_stall>0.3391428111</alpha_stall>
      <cla_stall>-3.85</cla_stall>
      <cda_stall>-0.9233984055</cda_stall>
      <cma_stall>0</cma_stall>
      <cp>-0.05 0.45 0.05</cp>
      <area>0.6</area>
      <air_density>1.2041</air_density>
      <forward>1 0 0</forward>
      <upward>0 0 1</upward>
      <link_name>base_link</link_name>
      <control_joint_name>
        left_elevon_joint
      </control_joint_name>
      <control_joint_rad_to_cl>-0.5</control_joint_rad_to_cl>
      <robotNamespace></robotNamespace>
      <windSubTopic>world_wind</windSubTopic>
    </plugin>
    <plugin name="right_wing" filename="libLiftDragPlugin.so">
      <a0>0.05984281113</a0>
      <cla>4.752798721</cla>
      <cda>0.6417112299</cda>
      <cma>0.0</cma>
      <alpha_stall>0.3391428111</alpha_stall>
      <cla_stall>-3.85</cla_stall>
      <cda_stall>-0.9233984055</cda_stall>
      <cma_stall>0</cma_stall>
      <cp>-0.05 -0.45 0.05</cp>
      <area>0.6</area>
      <air_density>1.2041</air_density>
      <forward>1 0 0</forward>
      <upward>0 0 1</upward>
      <link_name>base_link</link_name>
      <control_joint_name>
        right_elevon_joint
      </control_joint_name>
      <control_joint_rad_to_cl>-0.5</control_joint_rad_to_cl>
      <robotNamespace></robotNamespace>
      <windSubTopic>world_wind</windSubTopic>
    </plugin>
    <plugin name="left_flap" filename="libLiftDragPlugin.so">
      <a0>0.05984281113</a0>
      <cla>4.752798721</cla>
      <cda>0.6417112299</cda>
      <cma>0.0</cma>
      <alpha_stall>0.3391428111</alpha_stall>
      <cla_stall>-3.85</cla_stall>
      <cda_stall>-0.9233984055</cda_stall>
      <cma_stall>0</cma_stall>
      <cp>-0.05 0.15 0.05</cp>
      <area>0.6</area>
      <air_density>1.2041</air_density>
      <forward>1 0 0</forward>
      <upward>0 0 1</upward>
      <link_name>base_link</link_name>
      <control_joint_name>
        left_flap_joint
      </control_joint_name>
      <control_joint_rad_to_cl>-0.5</control_joint_rad_to_cl>
      <robotNamespace></robotNamespace>
      <windSubTopic>world_wind</windSubTopic>
    </plugin>
    <plugin name="right_flap" filename="libLiftDragPlugin.so">
      <a0>0.05984281113</a0>
      <cla>4.752798721</cla>
      <cda>0.6417112299</cda>
      <cma>0.0</cma>
      <alpha_stall>0.3391428111</alpha_stall>
      <cla_stall>-3.85</cla_stall>
      <cda_stall>-0.9233984055</cda_stall>
      <cma_stall>0</cma_stall>
      <cp>-0.05 -0.15 0.05</cp>
      <area>0.6</area>
      <air_density>1.2041</air_density>
      <forward>1 0 0</forward>
      <upward>0 0 1</upward>
      <link_name>base_link</link_name>
      <control_joint_name>
        right_flap_joint
      </control_joint_name>
      <control_joint_rad_to_cl>-0.5</control_joint_rad_to_cl>
      <robotNamespace></robotNamespace>
      <windSubTopic>world_wind</windSubTopic>
    </plugin>
    <plugin name="elevator" filename="libLiftDragPlugin.so">
      <a0>-0.2</a0>
      <cla>4.752798721</cla>
      <cda>0.6417112299</cda>
      <cma>0.0</cma>
      <alpha_stall>0.3391428111</alpha_stall>
      <cla_stall>-3.85</cla_stall>
      <cda_stall>-0.9233984055</cda_stall>
      <cma_stall>0</cma_stall>
      <cp>-0.5 0 0</cp>
      <area>0.01</area>
      <air_density>1.2041</air_density>
      <forward>1 0 0</forward>
      <upward>0 0 1</upward>
      <link_name>base_link</link_name>
      <control_joint_name>
        elevator_joint
      </control_joint_name>
      <control_joint_rad_to_cl>-4.0</control_joint_rad_to_cl>
      <robotNamespace></robotNamespace>
      <windSubTopic>world_wind</windSubTopic>
    </plugin>
    <plugin name="rudder" filename="libLiftDragPlugin.so">
      <a0>0.0</a0>
      <cla>4.752798721</cla>
      <cda>0.6417112299</cda>
      <cma>0.0</cma>
      <alpha_stall>0.3391428111</alpha_stall>
      <cla_stall>-3.85</cla_stall>
      <cda_stall>-0.9233984055</cda_stall>
      <cma_stall>0</cma_stall>
      <cp>-0.5 0 0.05</cp>
      <area>0.02</area>
      <air_density>1.2041</air_density>
      <forward>1 0 0</forward>
      <upward>0 1 0</upward>
      <link_name>base_link</link_name>
      <control_joint_name> 
         rudder_joint 
      </control_joint_name> 
      <control_joint_rad_to_cl>4.0</control_joint_rad_to_cl>
      <robotNamespace></robotNamespace>
      <windSubTopic>world_wind</windSubTopic>
    </plugin>
    <plugin name='puller' filename='libgazebo_motor_model.so'>
      <robotNamespace></robotNamespace>
      <jointName>rotor_puller_joint</jointName>
      <linkName>rotor_puller</linkName>
      <turningDirection>cw</turningDirection>
      <timeConstantUp>0.0125</timeConstantUp>
      <timeConstantDown>0.025</timeConstantDown>
      <maxRotVelocity>3500</maxRotVelocity>
      <motorConstant>8.54858e-06</motorConstant>
      <momentConstant>0.01</momentConstant>
      <commandSubTopic>/gazebo/command/motor_speed</commandSubTopic>
      <motorNumber>4</motorNumber>
      <rotorDragCoefficient>8.06428e-05</rotorDragCoefficient>
      <rollingMomentCoefficient>1e-06</rollingMomentCoefficient>
      <motorSpeedPubTopic>/motor_speed/4</motorSpeedPubTopic>
      <rotorVelocitySlowdownSim>10</rotorVelocitySlowdownSim>
      <robotNamespace></robotNamespace>
      <windSubTopic>world_wind</windSubTopic>
    </plugin>
    <plugin name='gazebo_imu_plugin' filename='libgazebo_imu_plugin.so'>
      <robotNamespace></robotNamespace>
      <linkName>plane_gimbal/imu_link</linkName>
      <imuTopic>/imu</imuTopic>
      <gyroscopeNoiseDensity>0.0003394</gyroscopeNoiseDensity>
      <gyroscopeRandomWalk>3.8785e-05</gyroscopeRandomWalk>
      <gyroscopeBiasCorrelationTime>1000.0</gyroscopeBiasCorrelationTime>
      <gyroscopeTurnOnBiasSigma>0.0087</gyroscopeTurnOnBiasSigma>
      <accelerometerNoiseDensity>0.004</accelerometerNoiseDensity>
      <accelerometerRandomWalk>0.006</accelerometerRandomWalk>
      <accelerometerBiasCorrelationTime>300.0</accelerometerBiasCorrelationTime>
      <accelerometerTurnOnBiasSigma>0.196</accelerometerTurnOnBiasSigma>
    </plugin>
    <plugin name='groundtruth_plugin' filename='libgazebo_groundtruth_plugin.so'>
      <robotNamespace/>
    </plugin>
    <plugin name='magnetometer_plugin' filename='libgazebo_magnetometer_plugin.so'>
      <robotNamespace/>
      <pubRate>100</pubRate>
      <noiseDensity>0.0004</noiseDensity>
      <randomWalk>6.4e-06</randomWalk>
      <biasCorrelationTime>600</biasCorrelationTime>
      <magTopic>/mag</magTopic>
    </plugin>
    <plugin name='barometer_plugin' filename='libgazebo_barometer_plugin.so'>
      <robotNamespace/>
      <pubRate>50</pubRate>
      <baroTopic>/baro</baroTopic>
    </plugin>
    <plugin name='airspeed_plugin' filename='libgazebo_airspeed_plugin.so'>
      <robotNamespace/>
      <linkName>plane_gimbal/airspeed_link</linkName>
    </plugin>

    <!--geotagged images camera-->
    <link name="cgo3_mount_link">
      <inertial>
        <!-- place holder -->
        <pose>-0.041 0 -0.162 0 0 0</pose>
        <mass>0.1</mass>
        <inertia>
          <ixx>0.001</ixx>
          <ixy>0</ixy>
          <ixz>0</ixz>
          <iyy>0.001</iyy>
          <iyz>0</iyz>
          <izz>0.001</izz>
        </inertia>
      </inertial>
      <visual name='cgo3_mount_visual'>
        <pose>0 0 0 0 0 0</pose>
        <geometry>
          <mesh>
            <scale>0.001 0.001 0.001</scale>
            <uri>model://typhoon_h480/meshes/cgo3_mount_remeshed_v1.stl</uri>
          </mesh>
        </geometry>
        <material>
          <script>
            <name>Gazebo/DarkGrey</name>
            <uri>file://media/materials/scripts/gazebo.material</uri>
          </script>
        </material>
      </visual>
    </link>
    <joint name='cgo3_mount_joint' type='revolute'>
      <child>cgo3_mount_link</child>
      <parent>base_link</parent>
      <pose>0 0 0 0 0 0</pose>
      <axis>
        <xyz>0 0 1</xyz>
        <limit>
          <lower>0</lower>
          <upper>0</upper>
          <effort>100</effort>
          <velocity>-1</velocity>
        </limit>
        <dynamics>
          <damping>1</damping>
        </dynamics>
        <use_parent_model_frame>1</use_parent_model_frame>
      </axis>
      <physics>
        <ode>
          <implicit_spring_damper>1</implicit_spring_damper>
        </ode>
      </physics>
    </joint>

    <link name="cgo3_vertical_arm_link">
      <inertial>
        <!-- place holder -->
        <pose>-0.041 0 -0.162 0 0 0</pose>
        <mass>0.1</mass>
        <inertia>
          <ixx>0.001</ixx>
          <ixy>0</ixy>
          <ixz>0</ixz>
          <iyy>0.001</iyy>
          <iyz>0</iyz>
          <izz>0.001</izz>
        </inertia>
      </inertial>
      <visual name='cgo3_vertical_arm_visual'>
        <pose>-0.051 0 0 0 0 3.141592</pose>
        <geometry>
          <mesh>
            <scale>0.001 0.001 0.001</scale>
            <uri>model://typhoon_h480/meshes/cgo3_vertical_arm_remeshed_v1.stl</uri>
          </mesh>
        </geometry>
        <material>
          <script>
            <name>Gazebo/DarkGrey</name>
            <uri>file://media/materials/scripts/gazebo.material</uri>
          </script>
        </material>
      </visual>
    </link>
    <joint name='cgo3_vertical_arm_joint' type='revolute'>
      <child>cgo3_vertical_arm_link</child>
      <parent>cgo3_mount_link</parent>
      <pose>-0.026 0 -0.10 0 0 0</pose>
      <!--
      <controlIndex>6</controlIndex>
      -->
      <axis>
        <xyz>0 0 1</xyz>
        <limit>
          <lower>-1e+16</lower>
          <upper>1e+16</upper>
          <effort>100</effort>
          <velocity>-1</velocity>
        </limit>
        <dynamics>
          <damping>0.1</damping>
        </dynamics>
        <use_parent_model_frame>1</use_parent_model_frame>
      </axis>
      <physics>
        <ode>
          <implicit_spring_damper>1</implicit_spring_damper>
          <limit>
            <!-- testing soft limits -->
            <cfm>0.1</cfm>
            <erp>0.2</erp>
          </limit>
        </ode>
      </physics>
    </joint>

    <link name="cgo3_horizontal_arm_link">
      <inertial>
        <!-- place holder -->
        <pose>-0.041 0 -0.081 0 0 0</pose>
        <mass>0.1</mass>
        <inertia>
          <ixx>0.001</ixx>
          <ixy>0</ixy>
          <ixz>0</ixz>
          <iyy>0.001</iyy>
          <iyz>0</iyz>
          <izz>0.001</izz>
        </inertia>
      </inertial>
      <visual name='cgo3_horizontal_arm_visual'>
        <pose>-0.05 0 0 0 0 3.141592</pose>
        <geometry>
          <mesh>
            <scale>0.001 0.001 0.001</scale>
            <uri>model://typhoon_h480/meshes/cgo3_horizontal_arm_remeshed_v1.stl</uri>
          </mesh>
        </geometry>
        <material>
          <script>
            <name>Gazebo/DarkGrey</name>
            <uri>file://media/materials/scripts/gazebo.material</uri>
          </script>
        </material>
      </visual>
    </link>
    <joint name='cgo3_horizontal_arm_joint' type='revolute'>
      <child>cgo3_horizontal_arm_link</child>
      <parent>cgo3_vertical_arm_link</parent>
      <pose>-0.07 0 -0.162 0 0 0</pose>
      <!--
      <controlIndex>7</controlIndex>
      -->
      <axis>
        <xyz>-1 0 0</xyz>
        <limit>
          <lower>-0.785398</lower>
          <upper>0.785398</upper>
          <effort>100</effort>
          <velocity>-1</velocity>
        </limit>
        <dynamics>
          <damping>0.1</damping>
        </dynamics>
        <use_parent_model_frame>1</use_parent_model_frame>
      </axis>
      <physics>
        <ode>
          <implicit_spring_damper>1</implicit_spring_damper>
          <limit>
            <!-- testing soft limits -->
            <cfm>0.1</cfm>
            <erp>0.2</erp>
          </limit>
        </ode>
      </physics>
    </joint>

    <link name="cgo3_camera_link">
      <inertial>
        <!-- place holder -->
        <pose>-0.041 0 -0.162 0 0 0</pose>
        <mass>0.1</mass>
        <inertia>
          <ixx>0.001</ixx>
          <ixy>0</ixy>
          <ixz>0</ixz>
          <iyy>0.001</iyy>
          <iyz>0</iyz>
          <izz>0.001</izz>
        </inertia>
      </inertial>
      <!-- <collision name='cgo3_camera_collision'>
        <pose>-0.041 0 -0.162 0 0 0</pose>
        <geometry>
          <sphere>
            <radius>0.035</radius>
          </sphere>
        </geometry>
        <surface>
          <friction>
            <ode>
              <mu>1</mu>
              <mu2>1</mu2>
            </ode>
          </friction>
          <contact>
            <ode>
              <kp>1e+8</kp>
              <kd>1</kd>
              <max_vel>0.01</max_vel>
              <min_depth>0.001</min_depth>
            </ode>
          </contact>
        </surface>
      </collision> -->
      <visual name='cgo3_camera_visual'>
        <pose>-0.05 0 0 0 0 3.141592</pose>
        <geometry>
          <mesh>
            <scale>0.001 0.001 0.001</scale>
            <uri>model://typhoon_h480/meshes/cgo3_camera_remeshed_v1.stl</uri>
          </mesh>
        </geometry>
        <material>
          <script>
            <name>Gazebo/DarkGrey</name>
            <uri>file://media/materials/scripts/gazebo.material</uri>
          </script>
        </material>
      </visual>
      <sensor name="camera_imu" type="imu">
        <always_on>1</always_on>
      </sensor>
      <sensor name="camera" type="camera">
        <pose>0.0 0 -0.162 0 0 0</pose>
        <camera>
          <horizontal_fov>2.0</horizontal_fov>
          <image>
            <format>R8G8B8</format>
            <width>640</width>
            <height>360</height>
          </image>
          <clip>
            <near>0.05</near>
            <far>15000</far>
          </clip>
        </camera>
        <always_on>1</always_on>
        <update_rate>10</update_rate>
        <visualize>true</visualize>
        <plugin name="GstCameraPlugin" filename="libgazebo_gst_camera_plugin.so">
            <robotNamespace></robotNamespace>
            <udpHost>127.0.0.1</udpHost>
            <udpPort>5600</udpPort>
        </plugin>
        <plugin name="CameraManagerPlugin" filename="libgazebo_camera_manager_plugin.so">
            <robotNamespace>plane_gimbal</robotNamespace>
            <interval>1</interval>
            <width>3840</width>
            <height>2160</height>
            <maximum_zoom>8.0</maximum_zoom>
            <video_uri>5600</video_uri>
            <system_id>1</system_id>
            <cam_component_id>100</cam_component_id>
            <mavlink_cam_udp_port>14530</mavlink_cam_udp_port>
        </plugin>
      </sensor>
    </link>
    <joint name='cgo3_camera_joint' type='revolute'>
      <child>cgo3_camera_link</child>
      <parent>cgo3_horizontal_arm_link</parent>
      <pose>-0.01 0.03 -0.162 0 0 0</pose>
      <axis>
        <xyz>0 -1 0</xyz>
        <limit>
          <lower>-1.5708</lower>
          <upper>0.7854</upper>
          <effort>100</effort>
          <velocity>-1</velocity>
        </limit>
        <dynamics>
          <damping>0.1</damping>
        </dynamics>
        <use_parent_model_frame>1</use_parent_model_frame>
      </axis>
      <physics>
        <ode>
          <implicit_spring_damper>1</implicit_spring_damper>
          <limit>
            <!-- testing soft limits -->
            <cfm>0.1</cfm>
            <erp>0.2</erp>
          </limit>
        </ode>
      </physics>
    </joint>

    <plugin name='gimbal_controller' filename='libgazebo_gimbal_controller_plugin.so'>
      <joint_yaw>plane_gimbal::cgo3_vertical_arm_joint</joint_yaw>
      <joint_roll>plane_gimbal::cgo3_horizontal_arm_joint</joint_roll>
      <joint_pitch>plane_gimbal::cgo3_camera_joint</joint_pitch>
      <control_gimbal_channels>
        <channel>
          <joint_control_pid>
            <p>0.4</p>
            <i>0.05</i>
            <d>0.02</d>
            <iMax>0</iMax>
            <iMin>0</iMin>
            <cmdMax>1.0</cmdMax>
            <cmdMin>-1.0</cmdMin>
          </joint_control_pid>
          <joint_axis>joint_yaw</joint_axis>
        </channel>
        <channel>
          <joint_control_pid>
            <p>0.8</p>
            <i>0.035</i>
            <d>0.02</d>
            <iMax>0</iMax>
            <iMin>0</iMin>
            <cmdMax>0.3</cmdMax>
            <cmdMin>-0.3</cmdMin>
          </joint_control_pid>
          <joint_axis>joint_roll</joint_axis>
        </channel>
        <channel>
          <joint_control_pid>
            <p>0.3</p>
            <i>0.01245</i>
            <d>0.015</d>
            <iMax>0</iMax>
            <iMin>0</iMin>
            <cmdMax>0.3</cmdMax>
            <cmdMin>-0.3</cmdMin>
          </joint_control_pid>
          <joint_axis>joint_pitch</joint_axis>
        </channel>
      </control_gimbal_channels>
      <gimbal_imu>camera_imu</gimbal_imu>
    </plugin>    

    <plugin name='mavlink_interface' filename='libgazebo_mavlink_interface.so'>
      <robotNamespace></robotNamespace>
      <imuSubTopic>/imu</imuSubTopic>
      <magSubTopic>/mag</magSubTopic>
      <baroSubTopic>/baro</baroSubTopic>
      <mavlink_addr>INADDR_ANY</mavlink_addr>
      <mavlink_tcp_port>4560</mavlink_tcp_port>
      <mavlink_udp_port>14560</mavlink_udp_port>
      <serialEnabled>0</serialEnabled>
      <serialDevice>/dev/ttyACM0</serialDevice>
      <baudRate>921600</baudRate>
      <qgc_addr>INADDR_ANY</qgc_addr>
      <qgc_udp_port>14550</qgc_udp_port>
      <sdk_addr>INADDR_ANY</sdk_addr>
      <sdk_udp_port>14540</sdk_udp_port>
      <hil_mode>0</hil_mode>
      <hil_state_level>false</hil_state_level>
      <enable_lockstep>true</enable_lockstep>
      <use_tcp>true</use_tcp>
      <motorSpeedCommandPubTopic>/gazebo/command/motor_speed</motorSpeedCommandPubTopic>
      <control_channels>
        <channel name="rudder">
          <input_index>2</input_index>
          <input_offset>0</input_offset>
          <input_scaling>1</input_scaling>
          <zero_position_disarmed>0</zero_position_disarmed>
          <zero_position_armed>0</zero_position_armed>
          <joint_control_type>position_kinematic</joint_control_type>
          <joint_name>rudder_joint</joint_name>
        </channel>
        <channel name="rotor4">
          <input_index>4</input_index>
          <input_offset>0</input_offset>
          <input_scaling>3500</input_scaling>
          <zero_position_disarmed>0</zero_position_disarmed>
          <zero_position_armed>0</zero_position_armed>
          <joint_control_type>velocity</joint_control_type>
          <joint_name>rotor_puller_joint</joint_name>
        </channel>
        <channel name="left_elevon">
          <input_index>5</input_index>
          <input_offset>0</input_offset>
          <input_scaling>1</input_scaling>
          <zero_position_disarmed>0</zero_position_disarmed>
          <zero_position_armed>0</zero_position_armed>
          <joint_control_type>position_kinematic</joint_control_type>
          <joint_name>left_elevon_joint</joint_name>
        </channel>
        <channel name="right_elevon">
          <input_index>6</input_index>
          <input_offset>0</input_offset>
          <input_scaling>1</input_scaling>
          <zero_position_disarmed>0</zero_position_disarmed>
          <zero_position_armed>0</zero_position_armed>
          <joint_control_type>position_kinematic</joint_control_type>
          <joint_name>right_elevon_joint</joint_name>
        </channel>
        <channel name="elevator">
          <input_index>7</input_index>
          <input_offset>0</input_offset>
          <input_scaling>1</input_scaling>
          <zero_position_disarmed>0</zero_position_disarmed>
          <zero_position_armed>0</zero_position_armed>
          <joint_control_type>position_kinematic</joint_control_type>
          <joint_name>elevator_joint</joint_name>
        </channel>
        <channel name="left_flap">
          <input_index>3</input_index>
          <input_offset>0</input_offset>
          <input_scaling>-1</input_scaling>
          <zero_position_disarmed>0</zero_position_disarmed>
          <zero_position_armed>0</zero_position_armed>
          <joint_control_type>position_kinematic</joint_control_type>
          <joint_name>left_flap_joint</joint_name>
        </channel>
        <channel name="right_flap">
          <input_index>8</input_index>
          <input_offset>0</input_offset>
          <input_scaling>-1</input_scaling>
          <zero_position_disarmed>0</zero_position_disarmed>
          <zero_position_armed>0</zero_position_armed>
          <joint_control_type>position_kinematic</joint_control_type>
          <joint_name>right_flap_joint</joint_name>
        </channel>
        <channel name="gimbal_roll">
          <input_index>9</input_index>
          <input_offset>0</input_offset>
          <input_scaling>-3.1415</input_scaling>
          <zero_position_disarmed>0</zero_position_disarmed>
          <zero_position_armed>0</zero_position_armed>
          <joint_control_type>position_gztopic</joint_control_type>
          <gztopic>/gimbal_roll_cmd</gztopic>
          <joint_name>plane_gimbal::cgo3_camera_joint</joint_name>
        </channel>
        <channel name="gimbal_pitch">
          <input_index>10</input_index>
          <input_offset>0</input_offset>
          <input_scaling>-3.1415</input_scaling>
          <zero_position_disarmed>0</zero_position_disarmed>
          <zero_position_armed>0</zero_position_armed>
          <joint_control_type>position_gztopic</joint_control_type>
          <gztopic>/gimbal_pitch_cmd</gztopic>
          <joint_name>plane_gimbal::cgo3_camera_joint</joint_name>
        </channel>
        <channel name="gimbal_yaw">
          <input_index>11</input_index>
          <input_offset>0</input_offset>
          <input_scaling>-3.1415</input_scaling>
          <zero_position_disarmed>0</zero_position_disarmed>
          <zero_position_armed>0</zero_position_armed>
          <joint_control_type>position_gztopic</joint_control_type>
          <gztopic>/gimbal_yaw_cmd</gztopic>
          <joint_name>plane_gimbal::cgo3_vertical_arm_joint</joint_name>
        </channel>
      </control_channels>
    </plugin>


  </model>
</sdf>
